Workbook

Sheet INFRASTRUKTUR
B2: KORPS SAMAPTA BHAYANGKARA BAHARKAM POLRI
B3: DIREKTORAT PAMOBVIT
B5: DAFTAR PENILAIAN RISIKO OBJEK WISATA
B7: NAMA OBJEK WISATA :
B8: ALAMAT :
B9: ASPEK INFRASTRUKTUR
B10: Bobot Elemen | C10: Kriteria | E10: Pencapaian Nilai Kriteria (0,1,2) | F10: Pencapaian Nilai Elemen | G10: Referensi Dokumen/ Rekaman | H10: Temuan | I10: Rekomendasi
C11: A. | D11: KELAIKAN GEDUNG/VENUE
B12: 0.12 | C12: 1 | D12: Memiliki parameter pembatas dengan lingkungan sekitar | E12: 0 | F12: =SUM(B12*E12)/48 -> 0
C13: 2 | D13: Memiliki pagar pembatas dan Gerbang Masuk | E13: 0 | F13: =SUM(B12*E13)/48 -> 0
C14: 3 | D14: Pos Penjagaan Utama/Depan | E14: 0 | F14: =SUM(B12*E14)/48 -> 0
C15: 4 | D15: Pos Penjagaan Belakang/Samping | E15: 0 | F15: =SUM(B12*E15)/48 -> 0
C16: 5 | D16: Pos bagian penurunan barang/loading dock | E16: 0 | F16: =SUM(B12*E16)/48 -> 0
C17: 6 | D17: Pos Bagian Dalam Objek | E17: 0 | F17: =SUM(B12*E17)/48 -> 0
C18: 7 | D18: Menara Pantau | E18: 0 | F18: =SUM(B12*E18)/48 -> 0
C19: 8 | D19: Ruang Kesehatan | E19: 0 | F19: =SUM(B12*E19)/48 -> 0
C20: 9 | D20: Ruang Monitoring Center/Kontrol | E20: 0 | F20: =SUM(B12*E20)/48 -> 0
C21: 10 | D21: Rambu/Tanda-tanda peringatan | E21: 0 | F21: =SUM(B12*E21)/48 -> 0
C22: 11 | D22: sistem Pencahayaan | E22: 0 | F22: =SUM(B12*E22)/48 -> 0
C23: 12 | D23: Ruang Power Supply | E23: 0 | F23: =SUM(B12*E23)/48 -> 0
C24: 13 | D24: Fasilitas bagi Difabel | E24: 0 | F24: =SUM(B12*E24)/48 -> 0
C25: 14 | D25: Jalur keluar masuk dan evakuasi | E25: 0 | F25: =SUM(B12*E25)/48 -> 0
C26: 15 | D26: Area parkir | E26: 0 | F26: =SUM(B12*E26)/48 -> 0
C27: 16 | D27: Menara pantau area parkir | E27: 0 | F27: =SUM(B12*E27)/48 -> 0
C28: 17 | D28: Jalur kendaraan | E28: 0 | F28: =SUM(B12*E28)/48 -> 0
C29: 18 | D29: Jalur pedestrian/assembling point | E29: 0 | F29: =SUM(B12*E29)/48 -> 0
C30: 19 | D30: Jalur dan fasilitas disabilitas | E30: 0 | F30: =SUM(B12*E30)/48 -> 0
C31: 20 | D31: Toilet/restroom pada ruang publik | E31: 0 | F31: =SUM(B12*E31)/48 -> 0
C32: 21 | D32: tempat penitipan barang | E32: 0 | F32: =SUM(B12*E32)/48 -> 0
C33: 22 | D33: Ruang Media/monitoring | E33: 0 | F33: =SUM(B12*E33)/48 -> 0
C34: 23 | D34: Area Foodcort | E34: 0 | F34: =SUM(B12*E34)/48 -> 0
C35: 24 | D35: Jalur evakusi VIP/VVIP (kendaraan darat, perairan dan udara) | E35: 0 | F35: =SUM(B12*E35)/48 -> 0
E36: Sub Total | F36: =SUM(F12:F35) -> 0
B37: 0.08 | C37: B. | D37: KELENGKAPAN HOTEL
C38: 1 | D38: Lampu lapangan/venue | E38: 0 | F38: =SUM(B37*E38)/20 -> 0
C39: 2 | D39: sistem CCTV | E39: 0 | F39: =SUM(B37*E39)/20 -> 0
C40: 3 | D40: Sarana komunikasi (HP, Handy Talky, videotron, intercome, Public address) | E40: 0 | F40: =SUM(B37*E40)/20 -> 0
C41: 4 | D41: Alarm tanda bahaya | E41: 0 | F41: =SUM(B37*E41)/20 -> 0
C42: 5 | D42: Tempat penampungan dan pengolahan limbah air kotor | E42: 0 | F42: =SUM(B37*E42)/20 -> 0
C43: 6 | D43: Fire system (hydrant system dan Apar) | E43: 0 | F43: =SUM(B37*E43)/20 -> 0
...

Sheet KEAMANAN
B4: ASPEK KEAMANAN
B6: Bobot Elemen | C6: Kriteria | E6: Pencapaian Nilai Kriteria (0,1,2) | F6: Pencapaian Nilai Elemen | G6: Referensi Dokumen/Rekaman | H6: Temuan | I6: Rekomendasi
B7: 0.2 | C7: A | D7: PROSEDUR PELAKSANA PENGAMANAN
C8: 1 | D8: Terdapat jadwal petugas pengamanan sesuai ketentuan yang berlaku | E8: 0 | F8: =SUM(B7*E8)/48 -> 0
C9: 2 | D9: memiliki struktur organisasi petugas pengamanan | E9: 0 | F9: =SUM(B7*E9)/48 -> 0
C10: 3 | D10: Terdapat Job Discription bagi seluruh komponen pengamanan | E10: 0 | F10: =SUM(B7*E10)/48 -> 0
C11: 4 | D11: pengamanan dilakukan dibagian depan (loby), bagian belakang (loadingdok) dan pintu masuk karyawan | E11: 0 | F11: =SUM(B7*E11)/48 -> 0
C12: 5 | D12: pengamanan dilaksanakan selama 24 jam | E12: 0 | F12: =SUM(B7*E12)/48 -> 0
C13: 6 | D13: roling/pergantian bergilir petugas patroli yang disesuaikan dengan luas area dan potensi ancaman | E13: 0 | F13: =SUM(B7*E13)/48 -> 0
C14: 7 | D14: sistem pelaporan melalui pencatatan mutasi kegiatan dan peristiwa menonjol | E14: 0 | F14: =SUM(B7*E14)/48 -> 0
C15: 8 | D15: prosedur terhadap pemeriksaan kendaraan dan orang yang masuk dan keluar area | E15: 0 | F15: =SUM(B7*E15)/48 -> 0
C16: 9 | D16: Terdapat SOP terhadap manajemen pelaksana pengamanan | E16: 0 | F16: =SUM(B7*E16)/48 -> 0
C17: 10 | D17: Terdapat SOP penanggulangan manajemen crowded dan darurat | E17: 0 | F17: =SUM(B7*E17)/48 -> 0
C18: 11 | D18: Terdapat SOP penanggulangan terorisme dan sabotas | E18: 0 | F18: =SUM(B7*E18)/48 -> 0
C19: 12 | D19: terdapat SOP pengamanan bagi karyawan selain petugas pengamanan | E19: 0 | F19: =SUM(B7*E19)/48 -> 0
E20: Sub Total | F20: =SUM(F8:F19) -> 0
C21: B | D21: PELAYANAN KEAMANAN
C22: 1 | D22: menyediakan peralatan keamanan berupa perlengkapan perorangan | E22: 0 | F22: =SUM(B7*E22)/40 -> 0
C23: 2 | D23: menyediakan peralatan pemeriksaan kendaraan dan badan yang masuk dan keluar area | E23: 0 | F23: =SUM(B7*E23)/40 -> 0
C24: 3 | D24: menyediakan peralatan sarana khusus berupa alat scaning atau Satwa Pelacak yang bersertifikat sesuai standar dan ketentuan yang berlaku | E24: 0 | F24: =SUM(B7*E24)/40 -> 0
C25: 4 | D25: Pelayanan Petugas Keamanan bersertifikat sesuai standar kualifikasinya | E25: 0 | F25: =SUM(B7*E25)/40 -> 0
C26: 5 | D26: Kelayakan dan perawatan berkala terhadap sarana/peralatan pengamanan | E26: 0 | F26: =SUM(B7*E26)/40 -> 0
C27: 6 | D27: menyediakan sarana pelaporan bagi pengunjung/karyawan | E27: 0 | F27: =SUM(B7*E27)/40 -> 0
C28: 7 | D28: Penempatan peralatan petugas keamanan pada objek sesaui dengan kerawanan | E28: 0 | F28: =SUM(B7*E28)/40 -> 0
C29: 8 | D29: terdapat SOP penggunaan peralatan keamanan | E29: 0 | F29: =SUM(B7*E29)/40 -> 0
C30: 9 | D30: Jalur komunikasi terhadap Satuan Kepolsiian terdekat | E30: 0 | F30: =SUM(B7*E30)/40 -> 0
C31: 10 | D31: Terdapat SOP kecepatan merespon dalam pelayanan keamanan | E31: 0 | F31: =SUM(B7*E31)/40 -> 0
E32: Sub Total | F32: =SUM(F22:F31) -> 0
D33: Sub Total | F33: =F32+F20 -> 0

Sheet KESELAMATAN
B3: ASPEK KESELAMATAN (WAHANA/VENUE WISATA YANG DISEDIAKAN)
B5: Bobot Elemen | C5: Kriteria | E5: Pencapaian Nilai Kriteria (0,1,2) | F5: Pencapaian Nilai Elemen | G5: Referensi Dokumen/Rekaman | H5: Temuan | I5: Rekomendasi
B6: 0.25 | C6: A | D6: PELAYANAN SISTEM KESELAMATAN
C7: 1 | D7: Kelayakan dan perawatan berkala terhadap sarana permainan/wahana/venue | E7: 0 | F7: =SUM(B6*E7)/50 -> 0
C8: 2 | D8: Penempatan wahana/venue sesuai dengan standar keselamatan | E8: 0 | F8: =SUM(B6*E8)/50 -> 0
C9: 3 | D9: terdapat sarana pendukung terhadap wahana/venue utama sebagai bagian dari sistem keselamatan bagi pengunjung | E9: 0 | F9: =SUM(B6*E9)/50 -> 0
C10: 4 | D10: terapat batas yang aman antara venue/wahana dengan petugas/pengunjung | E10: 0 | F10: =SUM(B6*E10)/50 -> 0
C11: 5 | D11: menyediakan peralatan keselamatan bagi pengunjung sesuai objek dan kapasitas pengunjung | E11: 0 | F11: =SUM(B6*E11)/50 -> 0
C12: 6 | D12: Peralatan/Sarana Prasarana petugas keselamatan sesuai objek | E12: 0 | F12: =SUM(B6*E12)/50 -> 0
C13: 7 | D13: terdapat pos pantau dengan posisi strategis bagi petugas keselamatan | E13: 0 | F13: =SUM(B6*E13)/50 -> 0
C14: 8 | D14: SOP Pembatasan pengunjung sesaui kapsitas wahana/venue | E14: 0 | F14: =SUM(B6*E14)/50 -> 0
C15: 9 | D15: Perawatan berkala dan penyimpanan, serta penempatan peralatan keselamatan sesuai dengan potensi ancaman | E15: 0 | F15: =SUM(B6*E15)/50 -> 0
C16: 10 | D16: dokumen uji kelayakan wahana/venue dari instansi yang berhak | E16: 0 | F16: =SUM(B6*E16)/50 -> 0
C17: 11 | D17: Batas/Rambu peringatan zona berbahaya/terlarang yang mudah terlihat dan mudah dipahami oleh pengunjung/petugas/karyawan/staf | E17: 0 | F17: =SUM(B6*E17)/50 -> 0
C18: 12 | D18: petunjuk arah dan denah lokasi wahana/venue | E18: 0 | F18: =SUM(B6*E18)/50 -> 0
C19: 13 | D19: aksesibilitas bagi penyandang difabel | E19: 0 | F19: =SUM(B6*E19)/50 -> 0
C20: 14 | D20: Sarana peringatan/informasi tentang situasi bahaya/kedaruratan yang mudah diakses/direspon oleh pengunjung | E20: 0 | F20: =SUM(B6*E20)/50 -> 0
C21: 15 | D21: SOP/KONSIGNES bagi staf dan pengujung Objek/Venue bilamana terjadi kedaruratan | E21: 0 | F21: =SUM(B6*E21)/50 -> 0
E22: Sub Total | F22: =SUM(F7:F21) -> 0
C23: B | D23: PETUGAS KESELAMATAN
C24: 1 | D24: Pelayanan Petugas Keselamatan memiliki kualifikasi sesuai dengan jenis/lokasi venue/wahana yang disediakan (Keselamatan air, Keselamatan vertikal/Ketinggian/Kedalaman, Pawang binatang, Teknisi permainan tertentu, dll) yang dibuktikan dengan sertifikat/keterangan telah mengikuti pelatihan | E24: 0 | F24: =SUM(B6*E24)/50 -> 0
C25: 2 | D25: kesesuaian jumlah petugas keselamatan dengan area kawasan | E25: 0 | F25: =SUM(B6*E25)/50 -> 0
C26: 3 | D26: memiliki SOP tentang penyelamatan dan pertolongan pertama | E26: 0 | F26: =SUM(B6*E26)/50 -> 0
C27: 4 | D27: memiliki SOP tentang jaring komando dan permintaan bantuan | E27: 0 | F27: =SUM(B6*E27)/50 -> 0
C28: 5 | D28: Prosedur evakuasi dan tanggap darurat yang jelas dan dapat diakses oleh pengunjung serta staf. | E28: 0 | F28: =SUM(B6*E28)/50 -> 0
C29: 6 | D29: Simulasi/latihan penanganan kedaruratan secara terpadu | E29: 0 | F29: =SUM(B6*E29)/50 -> 0
C30: 7 | D30: SOP/KONSIGNES bagi pengunjung Objek/Venue bilamana terjadi kedaruratan | E30: 0 | F30: =SUM(B6*E30)/50 -> 0
C31: 8 | D31: dilakukan patroli dan monitoring SOP/Konsignes bagi staf dan pengunjung untuk mematuhi ketentuan keselamatan dan kedaruratan | E31: 0 | F31: =SUM(B6*E31)/50 -> 0
C32: 9 | D32: pendokumentasian peristiwa kecelakaan dan gangguan keselamatan yang pernah terjadi | E32: 0 | F32: =SUM(B6*E32)/50 -> 0
C33: 10 | D33: dokumen analisa dan evaluasi hasil penanganan kecelakaan dan upaya pencegahannya | E33: 0 | F33: =SUM(B6*E33)/50 -> 0
E34: Sub Total | F34: =SUM(F24:F33) -> 0
D35: Sub Total | F35: =SUM(F22,F34) -> 0

Sheet KESEHATAN
B3: ASPEK KESEHATAN
B5: Bobot Elemen | C5: Kriteria | E5: Pencapaian Nilai Kriteria (0,1,2) | F5: Pencapaian Nilai Elemen | G5: Referensi Dokumen/Rekaman | H5: Temuan | I5: Rekomendasi
B6: 0.1 | C6: AB | D6: PROSEDUR PETUGAS MEDIS
C7: 1 | D7: Terdapat SOP manajemen petugas medis terhadap penanganan Staf dan Pengunjung | E7: 0 | F7: =SUM(B6*E7)/40 -> 0
C8: 2 | D8: Terdapat SOP manajemen petugas medis terhadap penanganan Staf dan Pengunjung saat terjadi kontijensi/kedaruratan | E8: 0 | F8: =SUM(B6*E8)/40 -> 0
C9: 3 | D9: Terdapat SOP manajemen petugas medis dalam penanganan VIP/VVIP | E9: 0 | F9: =SUM(B6*E9)/40 -> 0
C10: 4 | D10: Terdapat prosedur disinfectan dan fogging pada benda-benda dan tempat-tempat yang berpotensi menjadi sarang penyakit | E10: 0 | F10: =SUM(B6*E10)/40 -> 0
C11: 5 | D11: pelatihan pertolongan pertama terhadap gangguan kesehatan oleh petugas kesehatan dan staf | E11: 0 | F11: =SUM(B6*E11)/40 -> 0
C12: 6 | D12: Rencana tindakan pertama hingga evakuasi dan RS rujukan terhadap staf dan pengujung | E12: 0 | F12: =SUM(B6*E12)/40 -> 0
E13: Sub Total | F13: =SUM(F7:F12) -> 0
C14: B | D14: PELAYANAN KESEHATAN
C15: 1 | D15: Kelayakan dan perawatan berkala terhadap sarana kesehatan yang disiapkan pengelola objek | E15: 0 | F15: =SUM(B6*E15)/40 -> 0
C16: 2 | D16: Pelayanan Petugas Kesehatan sesuai standar/bersertifikat sesuai kualifikasinya | E16: 0 | F16: =SUM(B6*E16)/40 -> 0
C17: 3 | D17: menyediakan peralatan kesehatan bagi staf dan pengunjung | E17: 0 | F17: =SUM(B6*E17)/40 -> 0
C18: 4 | D18: terdapat Peralatan petugas kesehatan yang sesuai dengan potensi gangguan kesehatan pada pengunjung | E18: 0 | F18: =SUM(B6*E18)/40 -> 0
E19: Sub Total | F19: =SUM(F15:F18) -> 0
C20: C | D20: PROSEDUR KESEHATAN
C21: 1 | D21: Miliki saluran pembuangan/sanitari sesuai dengan stadar kesehatan | E21: 0 | F21: =SUM(B6*E21)/20 -> 0
C22: 2 | D22: Memiliki Sistem pembuangan Sampah dengan benar dan area pembuangan yang dijaga kebersihannya untuk mencegah timbulnya penyakit | E22: 0 | F22: =SUM(B6*E22)/20 -> 0
C23: 3 | D23: Terdapat pengolahan limbah dapur dan pengolahan air kotor | E23: 0 | F23: =SUM(B6*E23)/20 -> 0
C24: 4 | D24: pengecekan kualitas air bersih secara berkala | E24: 0 | F24: =SUM(B6*E24)/20 -> 0
C25: 5 | D25: prosedur pemisahan sampah organik, non organik dan sampah medis sesuai standar kesehatan | E25: 0 | F25: =SUM(B6*E25)/20 -> 0
E26: Sub Total | F26: =SUM(F21:F25) -> 0
D27: Sub Total | F27: =F26+F19+F13 -> 0

Sheet SISTEM PAM
B3: ASPEK KEAMANAN PADA SISTEM PENGAMANAN
B5: Bobot Elemen | C5: Kriteria | E5: Pencapaian Nilai Kriteria (0,1,2) | F5: Pencapaian Nilai Elemen | G5: Referensi Dokumen/Rekaman | H5: Temuan | I5: Rekomendasi
B6: 0.15 | C6: A | D6: ANALISA RISIKO KEAMANAN
C7: 1 | D7: Terdapat analisa data potensi gangguan | E7: 0 | F7: =SUM(B6*E7)/40 -> 0
C8: 2 | D8: Terdapat analisa risiko | E8: 0 | F8: =SUM(B6*E8)/40 -> 0
C9: 3 | D9: Terdapat penilaian risiko | E9: 0 | F9: =SUM(B6*E9)/40 -> 0
C10: 4 | D10: Adanya pengendalian risiko melalui Rencana Pengamanan yang tersutruktur | E10: 0 | F10: =SUM(B6*E10)/40 -> 0
E11: Sub Total | F11: =SUM(F7:F10) -> 0
C12: B | D12: PELAKSANAAN KEGIATAN PAM
C13: 1 | D13: memiliki kebijakan keamanan yang jelas yang mencakup prosedur untuk menangani insiden keamanan, kehilangan barang, dan tindakan darurat. | E13: 0 | F13: =SUM(B6*E13)/60 -> 0
C14: 2 | D14: Seluruh staf mengetahui prosedur untuk melaporkan insiden keamanan atau kejadian mencurigakan kepada manajemen atau pihak berwenang. | E14: 0 | F14: =SUM(B6*E14)/60 -> 0
C15: 3 | D15: Melaksanakan sistem pengamanan melalui:
C16: a | D16: adanya pola pengamanan (Pam) yang terdiri dari bentuk dan sifat Pam terbuka dan tertutup | E16: 0 | F16: =SUM(B6*E16)/60 -> 0
C17: b | D17: terdapat sarana dan area Pam, meliputi manusia dan fasilitas Pam | E17: 0 | F17: =SUM(B6*E17)/60 -> 0
C18: c | D18: terselenggaranya Komando dan pengendalian dalam dinamika Ops Sispam | E18: 0 | F18: =SUM(B6*E18)/60 -> 0
C19: 4 | D19: Konfigurasi pengamanan
C20: a | D20: tersedianya komponen pengamanan (Pam Internal) yang terstruktur | E20: 0 | F20: =SUM(B6*E20)/60 -> 0
C21: b | D21: terdapat penetapan dan pembinaan area pengamanan (area bebas, area terbatas, area terlarang) | E21: 0 | F21: =SUM(B6*E21)/60 -> 0
C22: c | D22: adanya konsep umum Pam serta ketersediaan personel Pam dan Sarpas yang cukup memadai | E22: 0 | F22: =SUM(B6*E22)/60 -> 0
C23: 5 | D23: Standar pelaksanaan pengamanan:
C24: a | D24: memiliki kopetensi sesuai dengan objek pengamanan dan resiko tugas | E24: 0 | F24: =SUM(B6*E24)/60 -> 0
C25: b | D25: memiliki komitmen dalam tugas | E25: 0 | F25: =SUM(B6*E25)/60 -> 0
C26: c | D26: Memiliki sikap humanis beretika dan tegas | E26: 0 | F26: =SUM(B6*E26)/60 -> 0
C27: d | D27: Sertifikasi sesuai bidang tugas/keahlian | E27: 0 | F27: =SUM(B6*E27)/60 -> 0
C28: 6 | D28: Monitoring dan evaluasi
C29: a | D29: Breefing/arahan dari atasan/pimpinan | E29: 0 | F29: =SUM(B6*E29)/60 -> 0
C30: b | D30: melaksanakan konsolidasi | E30: 0 | F30: =SUM(B6*E30)/60 -> 0
C31: c | D31: membuat laporan tertulis dan evaluasi | E31: 0 | F31: =SUM(B6*E31)/60 -> 0
C32: 7 | D32: Terdapat catatan peristiwa gangguan keamanan yang terdomkumentasi secara tertib dan lengkap | E32: 0 | F32: =SUM(B6*E32)/60 -> 0
E33: Sub Total | F33: =SUM(F13:F32) -> 0
C34: C | D34: PENGENDALIAN AKSES
C35: 1 | D35: Dilengkapi penggunaan kartu kunci elektronik yang dapat diaktifkan atau dinonaktifkan sesuai dengan status tamu dan area yang diizinkan | E35: 0 | F35: =SUM(B6*E35)/30 -> 0
C36: 2 | D36: Terdapat sistem yang membatasi akses ke area tertentu hanya untuk staf yang berwenang, seperti ruang mesin, gudang, atau area layanan | E36: 0 | F36: =SUM(B6*E36)/30 -> 0
C37: 3 | D37: monitoring dan pengawasan terhadap akses terbatas melalui penggunaan CCTV dan sistem alarm | E37: 0 | F37: =SUM(B6*E37)/30 -> 0
C38: 4 | D38: terdapat SOP untuk mengendalikan dan melakukan tindakan pertama terhadap pelanggaran/situasi darurat sebagai akibat dari kesalahan penggunaan akses | E38: 0 | F38: =SUM(B6*E38)/30 -> 0
E39: Sub Total | F39: =SUM(F35:F38) -> 0
D40: Sub Total | F40: =F39+F33+F11 -> 0

Sheet INFORMASI
B3: INFORMASI
B5: Bobot Elemen | C5: Kriteria | E5: Pencapaian Nilai Kriteria (0,1,2) | F5: Pencapaian Nilai Elemen | G5: Referensi Dokumen/Rekaman | H5: Temuan | I5: Rekomendasi
B6: 0.1 | D6: INFORMASI
C7: 1 | D7: Terdapat sarana dan sumber informasi yang mudah diakses oleh staf dan pengunjung | E7: 0 | F7: =SUM(B6*E7)/20 -> 0
C8: 2 | D8: Terdapat sistem informasi yang bersifat segera/mendesak beurupa alarm Peringatan/larangan/tanda bahaya | E8: 0 | F8: =SUM(B6*E8)/20 -> 0
C9: 3 | D9: Terdapat nomor telpon pengaduan/pelaporan kedaruratan | E9: 0 | F9: =SUM(B6*E9)/20 -> 0
C10: 4 | D10: terdapat sarana penyampaian informasi segera yang bersumber dari staf/pengunjung | E10: 0 | F10: =SUM(B6*E10)/20 -> 0
C11: 5 | D11: tersedia sarana pengaduan dari pengunjung | E11: 0 | F11: =SUM(B6*E11)/20 -> 0
C12: 6 | D12: Terdapat media informasi secara visual bagi staf dan pengunjung (video tron, media sosial dan rambu petunjuk dan papan pengumuman) | E12: 0 | F12: =SUM(B6*E12)/20 -> 0
C13: 7 | D13: terdapat SOP terhadap penyampaian informasi yang meliputi keakuratan, ketepatan waktu dan keotentikan sumber informasi | E13: 0 | F13: =SUM(B6*E13)/20 -> 0
C14: 8 | D14: terdapat sarana komunikasi atar staf dalam penyampaian informasi yang bersifat internal | E14: 0 | F14: =SUM(B6*E14)/20 -> 0
C15: 9 | D15: dilakukan pembaruan informasi sesuai perkembangan situasi dan kondisi serta kebutuhan | E15: 0 | F15: =SUM(B6*E15)/20 -> 0
C16: 10 | D16: perawatan dan pemeliharaan terhadap sarana informasi secara berkala dan sesaui standar | E16: 0 | F16: =SUM(B6*E16)/20 -> 0
D17: Sub Total | E17: Sub Total | F17: =SUM(F7:F16) -> 0
H22: …....... , ….. …............ …....
E23: SAFETY MANAGER….... | H23: KETUA TIM
E27: NAMA | H27: NAMA
H28: PANGKAT/NRP

Sheet Skor Final
B1: SKOR FINAL
B3: Elemen | C3: Penjelasan | D3: Bobot | E3: Pencapaian
B4: 1 | C4: ASPEK INFRASTRUKTUR | D4: 0.2 | E4: =INFRASTRUKTUR!F49 -> 0
B5: 2 | C5: ASPEK KEAMANAN | D5: 0.2 | E5: =KEAMANAN!F33 -> 0
B6: 3 | C6: ASPEK KESELAMATAN | D6: 0.25 | E6: =KESELAMATAN!F35 -> 0
B7: 4 | C7: ASPEK KESEHATAN | D7: 0.1 | E7: =KESEHATAN!F27 -> 0
B8: 5 | C8: ASPEK SISTEM PENGAMANAN | D8: 0.15 | E8: ='SISTEM PAM'!F40 -> 0
B9: 6 | C9: ASPEK INFORMASI | D9: 0.1 | E9: =INFORMASI!F17 -> 0
B10: Total | D10: =SUM(D4:D9) -> 1 | E10: =SUM(E4:E9) -> 0
B11: Kategori | E11: =IF(E10<55%,"Kurang",IF(E10<70%,"Perunggu",IF(E10<85%,"Perak","Emas"))) -> Kurang
B13: 86% - 100% | C13: Baik Sekali (Kategori Emas)
B14: 71% - 85% | C14: Baik (Kategori Perak)
B15: 56% - 70% | C15: Cukup (Kategori Perunggu)
B16: < 55% | C16: Kurang (Tindakan Pembinaan untuk Perbaikan)
